Workbook

Sheet 영어 단어장
A1: No. | B1: 영어 단어 | C1: 뜻 | D1: 예문 | E1: 암기 체크 | F1: 입력 날짜 | G1: 오답 체크 | H1: 중복 체크 | I1: 구분
A2: 1 | B2: eloquent | C2: 유창한, 설득력 있는 | D2: She gave an eloquent speech that moved the audience to tears. | F2: 46098 | G2: =IF('단어 시험장'!E2="❌","❌","") | H2: {=IF(B2="","",IF(COUNTIF($B$2:$B$501,B2)>1,"No."&_xlfn.TEXTJOIN(", ",TRUE,IF(($B$2:$B$501=B2)*(ROW($B$2:$B$501)<>ROW(B2)),""&$A$2:$A$501,"")),""))}
A3: 2 | B3: mundane | C3: 평범한, 일상적인 | D3: He wanted to escape his mundane daily routine. | F3: 46098 | G3: =IF('단어 시험장'!E3="❌","❌","") | H3: {=IF(B3="","",IF(COUNTIF($B$2:$B$501,B3)>1,"No."&_xlfn.TEXTJOIN(", ",TRUE,IF(($B$2:$B$501=B3)*(ROW($B$2:$B$501)<>ROW(B3)),""&$A$2:$A$501,"")),""))}
A4: 3 | B4: scurtinize | C4: 정밀 검토하다 | D4: The auditor scrutinized every line of the financial report. | F4: 46098 | G4: =IF('단어 시험장'!E4="❌","❌","") -> ❌ | H4: {=IF(B4="","",IF(COUNTIF($B$2:$B$501,B4)>1,"No."&_xlfn.TEXTJOIN(", ",TRUE,IF(($B$2:$B$501=B4)*(ROW($B$2:$B$501)<>ROW(B4)),""&$A$2:$A$501,"")),""))}
A5: 4 | B5: pragmatic | C5: 실용적인 | D5: We need a pragmatic solution, not just a theory. | F5: 46098 | G5: =IF('단어 시험장'!E5="❌","❌","") | H5: {=IF(B5="","",IF(COUNTIF($B$2:$B$501,B5)>1,"No."&_xlfn.TEXTJOIN(", ",TRUE,IF(($B$2:$B$501=B5)*(ROW($B$2:$B$501)<>ROW(B5)),""&$A$2:$A$501,"")),""))}
A6: 5 | B6: ambiguous | C6: 애매한, 모호한 | D6: The contract was too ambiguous to sign. | F6: 46098 | G6: =IF('단어 시험장'!E6="❌","❌","") | H6: {=IF(B6="","",IF(COUNTIF($B$2:$B$501,B6)>1,"No."&_xlfn.TEXTJOIN(", ",TRUE,IF(($B$2:$B$501=B6)*(ROW($B$2:$B$501)<>ROW(B6)),""&$A$2:$A$501,"")),""))}
A7: 6 | B7: volatile | C7: 변덕스러운 | D7: The stock market has been extremely volatile this year. | F7: 46098 | G7: =IF('단어 시험장'!E7="❌","❌","") | H7: {=IF(B7="","",IF(COUNTIF($B$2:$B$501,B7)>1,"No."&_xlfn.TEXTJOIN(", ",TRUE,IF(($B$2:$B$501=B7)*(ROW($B$2:$B$501)<>ROW(B7)),""&$A$2:$A$501,"")),""))}
A8: 7 | B8: contemplate | C8: 숙고하다 | D8: She sat quietly to contemplate her future career. | F8: 46098 | G8: =IF('단어 시험장'!E8="❌","❌","") | H8: {=IF(B8="","",IF(COUNTIF($B$2:$B$501,B8)>1,"No."&_xlfn.TEXTJOIN(", ",TRUE,IF(($B$2:$B$501=B8)*(ROW($B$2:$B$501)<>ROW(B8)),""&$A$2:$A$501,"")),""))} -> No.114
A9: 8 | B9: meticulous | C9: 꼼꼼한, 세심한 | D9: He is meticulous about keeping his desk organized. | F9: 46098 | G9: =IF('단어 시험장'!E9="❌","❌","") | H9: {=IF(B9="","",IF(COUNTIF($B$2:$B$501,B9)>1,"No."&_xlfn.TEXTJOIN(", ",TRUE,IF(($B$2:$B$501=B9)*(ROW($B$2:$B$501)<>ROW(B9)),""&$A$2:$A$501,"")),""))}
A10: 9 | B10: perpetual | C10: 영구적인 | D10: The noise from the construction was perpetual. | F10: 46098 | G10: =IF('단어 시험장'!E10="❌","❌","") | H10: {=IF(B10="","",IF(COUNTIF($B$2:$B$501,B10)>1,"No."&_xlfn.TEXTJOIN(", ",TRUE,IF(($B$2:$B$501=B10)*(ROW($B$2:$B$501)<>ROW(B10)),""&$A$2:$A$501,"")),""))}
A11: 10 | B11: redundant | C11: 중복된, 불필요한 | D11: We should remove redundant steps from the process. | F11: 46098 | G11: =IF('단어 시험장'!E11="❌","❌","") | H11: {=IF(B11="","",IF(COUNTIF($B$2:$B$501,B11)>1,"No."&_xlfn.TEXTJOIN(", ",TRUE,IF(($B$2:$B$501=B11)*(ROW($B$2:$B$501)<>ROW(B11)),""&$A$2:$A$501,"")),""))}
A12: 11 | B12: adequate | C12: 적절한, 충분한 | D12: The budget is adequate for the project. | F12: 46098 | G12: =IF('단어 시험장'!E12="❌","❌","") | H12: {=IF(B12="","",IF(COUNTIF($B$2:$B$501,B12)>1,"No."&_xlfn.TEXTJOIN(", ",TRUE,IF(($B$2:$B$501=B12)*(ROW($B$2:$B$501)<>ROW(B12)),""&$A$2:$A$501,"")),""))}
A13: 12 | B13: reluctant | C13: 꺼리는 | D13: He was reluctant to accept the new position. | F13: 46098 | G13: =IF('단어 시험장'!E13="❌","❌","") | H13: {=IF(B13="","",IF(COUNTIF($B$2:$B$501,B13)>1,"No."&_xlfn.TEXTJOIN(", ",TRUE,IF(($B$2:$B$501=B13)*(ROW($B$2:$B$501)<>ROW(B13)),""&$A$2:$A$501,"")),""))}
... A359: 358 | B359: tendency | C359: 경향, 추세 | D359: There is a growing tendency for people to shop online. | F359: 45737 | G359: =IF('단어 시험장'!E359="❌","❌","") | H359: {=IF(B359="","",IF(COUNTIF($B$2:$B$501,B359)>1,"No."&_xlfn.TEXTJOIN(", ",TRUE,IF(($B$2:$B$501=B359)*(ROW($B$2:$B$501)<>ROW(B359)),""&$A$2:$A$501,"")),""))}
A360: 359 | B360: abandon | C360: 버리다, 포기하다 | D360: They abandoned the old factory and moved to a new location. | F360: 45745 | G360: =IF('단어 시험장'!E360="❌","❌","") | H360: {=IF(B360="","",IF(COUNTIF($B$2:$B$501,B360)>1,"No."&_xlfn.TEXTJOIN(", ",TRUE,IF(($B$2:$B$501=B360)*(ROW($B$2:$B$501)<>ROW(B360)),""&$A$2:$A$501,"")),""))} | I360: Day1
A361: 360 | B361: forsake | C361: 버리다, 저버리다 | D361: He promised never to forsake his friends in times of trouble. | F361: 45745 | G361: =IF('단어 시험장'!E361="❌","❌","") | H361: {=IF(B361="","",IF(COUNTIF($B$2:$B$501,B361)>1,"No."&_xlfn.TEXTJOIN(", ",TRUE,IF(($B$2:$B$501=B361)*(ROW($B$2:$B$501)<>ROW(B361)),""&$A$2:$A$501,"")),""))} | I361: Day1
A362: 361 | B362: surrender | C362: 항복, 넘겨주다 | D362: The army was forced to surrender after a long battle. | F362: 45745 | G362: =IF('단어 시험장'!E362="❌","❌","") | H362: {=IF(B362="","",IF(COUNTIF($B$2:$B$501,B362)>1,"No."&_xlfn.TEXTJOIN(", ",TRUE,IF(($B$2:$B$501=B362)*(ROW($B$2:$B$501)<>ROW(B362)),""&$A$2:$A$501,"")),""))} | I362: Day1
A363: 362 | B363: hand over | C363: 넘겨주다 | D363: The manager was asked to hand over all the documents. | F363: 45745 | G363: =IF('단어 시험장'!E363="❌","❌","") | H363: {=IF(B363="","",IF(COUNTIF($B$2:$B$501,B363)>1,"No."&_xlfn.TEXTJOIN(", ",TRUE,IF(($B$2:$B$501=B363)*(ROW($B$2:$B$501)<>ROW(B363)),""&$A$2:$A$501,"")),""))} | I363: Day1
A364: 363 | B364: dump | C364: 내버리다 | D364: Illegal dumping of waste can seriously harm the environment. | F364: 45745 | G364: =IF('단어 시험장'!E364="❌","❌","") | H364: {=IF(B364="","",IF(COUNTIF($B$2:$B$501,B364)>1,"No."&_xlfn.TEXTJOIN(", ",TRUE,IF(($B$2:$B$501=B364)*(ROW($B$2:$B$501)<>ROW(B364)),""&$A$2:$A$501,"")),""))} | I364: Day1
A365: 364 | B365: dismiss | C365: 해고하다 | D365: The company dismissed several employees due to budget cuts. | F365: 45745 | G365: =IF('단어 시험장'!E365="❌","❌","") | H365: {=IF(B365="","",IF(COUNTIF($B$2:$B$501,B365)>1,"No."&_xlfn.TEXTJOIN(", ",TRUE,IF(($B$2:$B$501=B365)*(ROW($B$2:$B$501)<>ROW(B365)),""&$A$2:$A$501,"")),""))} -> No.123 | I365: Day1
A366: 365 | B366: relinquish | C366: 포기하다, 단념하다 | D366: She was reluctant to relinquish control of the project. | E366: ❌ | F366: 45745 | G366: =IF('단어 시험장'!E366="❌","❌","") | H366: {=IF(B366="","",IF(COUNTIF($B$2:$B$501,B366)>1,"No."&_xlfn.TEXTJOIN(", ",TRUE,IF(($B$2:$B$501=B366)*(ROW($B$2:$B$501)<>ROW(B366)),""&$A$2:$A$501,"")),""))} | I366: Day1
A367: 366 | B367: resign | C367: 포기하다, 사임하다 | D367: He resigned from his position as CEO last month. | F367: 45745 | G367: =IF('단어 시험장'!E367="❌","❌","") | H367: {=IF(B367="","",IF(COUNTIF($B$2:$B$501,B367)>1,"No."&_xlfn.TEXTJOIN(", ",TRUE,IF(($B$2:$B$501=B367)*(ROW($B$2:$B$501)<>ROW(B367)),""&$A$2:$A$501,"")),""))} | I367: Day1
A368: 367 | B368: discard | C368: 버리다, 해고하다 | D368: Please discard any expired products from the shelf. | F368: 45745 | G368: =IF('단어 시험장'!E368="❌","❌","") | H368: {=IF(B368="","",IF(COUNTIF($B$2:$B$501,B368)>1,"No."&_xlfn.TEXTJOIN(", ",TRUE,IF(($B$2:$B$501=B368)*(ROW($B$2:$B$501)<>ROW(B368)),""&$A$2:$A$501,"")),""))} | I368: Day1
A369: 368 | B369: desert | C369: 버리다, 도망가다 / 사막 | D369: The soldier deserted his unit and fled across the border. | F369: 45745 | G369: =IF('단어 시험장'!E369="❌","❌","") | H369: {=IF(B369="","",IF(COUNTIF($B$2:$B$501,B369)>1,"No."&_xlfn.TEXTJOIN(", ",TRUE,IF(($B$2:$B$501=B369)*(ROW($B$2:$B$501)<>ROW(B369)),""&$A$2:$A$501,"")),""))} | I369: Day1
A370: 369 | B370: yield | C370: 산출하다, 수확 | D370: The investment yielded a high return this year. | F370: 45745 | G370: =IF('단어 시험장'!E370="❌","❌","") | H370: {=IF(B370="","",IF(COUNTIF($B$2:$B$501,B370)>1,"No."&_xlfn.TEXTJOIN(", ",TRUE,IF(($B$2:$B$501=B370)*(ROW($B$2:$B$501)<>ROW(B370)),""&$A$2:$A$501,"")),""))} | I370: Day1
A371: 370 | B371: grasp | C371: 움켜집다, 파악하다 | D371: It took me a while to grasp the concept of calculus. | F371: 45745 | G371: =IF('단어 시험장'!E371="❌","❌","") | H371: {=IF(B371="","",IF(COUNTIF($B$2:$B$501,B371)>1,"No."&_xlfn.TEXTJOIN(", ",TRUE,IF(($B$2:$B$501=B371)*(ROW($B$2:$B$501)<>ROW(B371)),""&$A$2:$A$501,"")),""))} | I371: Day1
A372: 371 | B372: seize | C372: 사로잡다, 이해하다 | D372: Police seized a large amount of illegal drugs at the border. | F372: 45745 | G372: =IF('단어 시험장'!E372="❌","❌","") | H372: {=IF(B372="","",IF(COUNTIF($B$2:$B$501,B372)>1,"No."&_xlfn.TEXTJOIN(", ",TRUE,IF(($B$2:$B$501=B372)*(ROW($B$2:$B$501)<>ROW(B372)),""&$A$2:$A$501,"")),""))} | I372: Day1
A373: 372 | B373: grip | C373: 꽉 쥐다, 손잡이 | D373: Fear gripped the passengers when the plane hit turbulence. | F373: 45745 | G373: =IF('단어 시험장'!E373="❌","❌","") | H373: {=IF(B373="","",IF(COUNTIF($B$2:$B$501,B373)>1,"No."&_xlfn.TEXTJOIN(", ",TRUE,IF(($B$2:$B$501=B373)*(ROW($B$2:$B$501)<>ROW(B373)),""&$A$2:$A$501,"")),""))} | I373: Day1
A374: 373 | B374: capture | C374: 잡다, 획득하다 | D374: The photographer captured a stunning image of the sunset. | F374: 45745 | G374: =IF('단어 시험장'!E374="❌","❌","") | H374: {=IF(B374="","",IF(COUNTIF($B$2:$B$501,B374)>1,"No."&_xlfn.TEXTJOIN(", ",TRUE,IF(($B$2:$B$501=B374)*(ROW($B$2:$B$501)<>ROW(B374)),""&$A$2:$A$501,"")),""))} | I374: Day1
A375: 374 | B375: snatch | C375: 잡아채다 | D375: The thief snatched her purse and ran away. | F375: 45745 | G375: =IF('단어 시험장'!E375="❌","❌","") | H375: {=IF(B375="","",IF(COUNTIF($B$2:$B$501,B375)>1,"No."&_xlfn.TEXTJOIN(", ",TRUE,IF(($B$2:$B$501=B375)*(ROW($B$2:$B$501)<>ROW(B375)),""&$A$2:$A$501,"")),""))} | I375: Day1
A376: 375 | B376: embrace | C376: 껴안다, 받아들이다 | D376: She embraced her daughter warmly after the long trip. | F376: 45745 | G376: =IF('단어 시험장'!E376="❌","❌","") | H376: {=IF(B376="","",IF(COUNTIF($B$2:$B$501,B376)>1,"No."&_xlfn.TEXTJOIN(", ",TRUE,IF(($B$2:$B$501=B376)*(ROW($B$2:$B$501)<>ROW(B376)),""&$A$2:$A$501,"")),""))} -> No.351 | I376: Day1
A377: 376 | B377: hostage | C377: 인질 | D377: The hostages were held for three days before being released. | F377: 45745 | G377: =IF('단어 시험장'!E377="❌","❌","") | H377: {=IF(B377="","",IF(COUNTIF($B$2:$B$501,B377)>1,"No."&_xlfn.TEXTJOIN(", ",TRUE,IF(($B$2:$B$501=B377)*(ROW($B$2:$B$501)<>ROW(B377)),""&$A$2:$A$501,"")),""))} | I377: Day1
A378: 377 | B378: abduct | C378: 유괴하다 | D378: The child was abducted from the park in broad daylight. | F378: 45745 | G378: =IF('단어 시험장'!E378="❌","❌","") | H378: {=IF(B378="","",IF(COUNTIF($B$2:$B$501,B378)>1,"No."&_xlfn.TEXTJOIN(", ",TRUE,IF(($B$2:$B$501=B378)*(ROW($B$2:$B$501)<>ROW(B378)),""&$A$2:$A$501,"")),""))} | I378: Day1
... A385: 384 | B385: wither | C385: 시들다, 위축시키다 | D385: The flowers withered quickly in the summer heat. | F385: 45745 | G385: =IF('단어 시험장'!E385="❌","❌","") | H385: {=IF(B385="","",IF(COUNTIF($B$2:$B$501,B385)>1,"No."&_xlfn.TEXTJOIN(", ",TRUE,IF(($B$2:$B$501=B385)*(ROW($B$2:$B$501)<>ROW(B385)),""&$A$2:$A$501,"")),""))} | I385: Day1
A386: 385 | B386: languish | C386: 시들다, 축 늘어지다 | D386: The economy languished for years after the financial crisis. | E386: ❌ | F386: 45745 | G386: =IF('단어 시험장'!E386="❌","❌","") | H386: {=IF(B386="","",IF(COUNTIF($B$2:$B$501,B386)>1,"No."&_xlfn.TEXTJOIN(", ",TRUE,IF(($B$2:$B$501=B386)*(ROW($B$2:$B$501)<>ROW(B386)),""&$A$2:$A$501,"")),""))} | I386: Day1
A387: 386 | B387: invalid | C387: 무효의 | D387: The court declared the contract invalid due to fraud. | F387: 45745 | G387: =IF('단어 시험장'!E387="❌","❌","") | H387: {=IF(B387="","",IF(COUNTIF($B$2:$B$501,B387)>1,"No."&_xlfn.TEXTJOIN(", ",TRUE,IF(($B$2:$B$501=B387)*(ROW($B$2:$B$501)<>ROW(B387)),""&$A$2:$A$501,"")),""))} | I387: Day1
A388: 387 | B388: faculty | C388: 능력, 재능 | D388: She has a remarkable faculty for learning new languages. | F388: 45745 | G388: =IF('단어 시험장'!E388="❌","❌","") | H388: {=IF(B388="","",IF(COUNTIF($B$2:$B$501,B388)>1,"No."&_xlfn.TEXTJOIN(", ",TRUE,IF(($B$2:$B$501=B388)*(ROW($B$2:$B$501)<>ROW(B388)),""&$A$2:$A$501,"")),""))} | I388: Day1
A389: 388 | B389: aptitude | C389: 재능, 적성 | D389: He showed a natural aptitude for mathematics from a young age. | F389: 45745 | G389: =IF('단어 시험장'!E389="❌","❌","") | H389: {=IF(B389="","",IF(COUNTIF($B$2:$B$501,B389)>1,"No."&_xlfn.TEXTJOIN(", ",TRUE,IF(($B$2:$B$501=B389)*(ROW($B$2:$B$501)<>ROW(B389)),""&$A$2:$A$501,"")),""))} | I389: Day1
A390: 389 | B390: removal | C390: 철수, 제거 | D390: The removal of the old bridge caused major traffic delays. | F390: 45745 | G390: =IF('단어 시험장'!E390="❌","❌","") | H390: {=IF(B390="","",IF(COUNTIF($B$2:$B$501,B390)>1,"No."&_xlfn.TEXTJOIN(", ",TRUE,IF(($B$2:$B$501=B390)*(ROW($B$2:$B$501)<>ROW(B390)),""&$A$2:$A$501,"")),""))} | I390: Day1
A391: 390 | B391: repeal | C391: 무효로 하다, 폐지하다 | D391: The government repealed the outdated law last year. | F391: 45745 | G391: =IF('단어 시험장'!E391="❌","❌","") | H391: {=IF(B391="","",IF(COUNTIF($B$2:$B$501,B391)>1,"No."&_xlfn.TEXTJOIN(", ",TRUE,IF(($B$2:$B$501=B391)*(ROW($B$2:$B$501)<>ROW(B391)),""&$A$2:$A$501,"")),""))} | I391: Day1
...

Sheet 단어 시험장
A1: No. | B1: 뜻 (문제) | C1: 내 답 | D1: 정답 | E1: 결과 | F1: 시험 날짜
A2: =ROW()-1 -> 1 | B2: =IF('영어 단어장'!C2="","",'영어 단어장'!C2) -> 유창한, 설득력 있는 | C2: eloquent | D2: =IF(OR(C2="",'영어 단어장'!B2=""),"",IF(EXACT(LOWER(TRIM(C2)),LOWER(TRIM('영어 단어장'!B2))),"",'영어 단어장'!B2)) | E2: =IF(OR(B2="",C2=""),"",IF(EXACT(LOWER(TRIM(C2)),LOWER(TRIM('영어 단어장'!B2))),"⭕","❌")) -> ⭕
A3: =ROW()-1 -> 2 | B3: =IF('영어 단어장'!C3="","",'영어 단어장'!C3) -> 평범한, 일상적인 | C3: mundane | D3: =IF(OR(C3="",'영어 단어장'!B3=""),"",IF(EXACT(LOWER(TRIM(C3)),LOWER(TRIM('영어 단어장'!B3))),"",'영어 단어장'!B3)) | E3: =IF(OR(B3="",C3=""),"",IF(EXACT(LOWER(TRIM(C3)),LOWER(TRIM('영어 단어장'!B3))),"⭕","❌")) -> ⭕
A4: =ROW()-1 -> 3 | B4: =IF('영어 단어장'!C4="","",'영어 단어장'!C4) -> 정밀 검토하다 | C4: scruticize | D4: =IF(OR(C4="",'영어 단어장'!B4=""),"",IF(EXACT(LOWER(TRIM(C4)),LOWER(TRIM('영어 단어장'!B4))),"",'영어 단어장'!B4)) -> scurtinize | E4: =IF(OR(B4="",C4=""),"",IF(EXACT(LOWER(TRIM(C4)),LOWER(TRIM('영어 단어장'!B4))),"⭕","❌")) -> ❌
A5: =ROW()-1 -> 4 | B5: =IF('영어 단어장'!C5="","",'영어 단어장'!C5) -> 실용적인 | C5: pragmatic | D5: =IF(OR(C5="",'영어 단어장'!B5=""),"",IF(EXACT(LOWER(TRIM(C5)),LOWER(TRIM('영어 단어장'!B5))),"",'영어 단어장'!B5)) | E5: =IF(OR(B5="",C5=""),"",IF(EXACT(LOWER(TRIM(C5)),LOWER(TRIM('영어 단어장'!B5))),"⭕","❌")) -> ⭕
A6: =ROW()-1 -> 5 | B6: =IF('영어 단어장'!C6="","",'영어 단어장'!C6) -> 애매한, 모호한 | C6: ambiguous | D6: =IF(OR(C6="",'영어 단어장'!B6=""),"",IF(EXACT(LOWER(TRIM(C6)),LOWER(TRIM('영어 단어장'!B6))),"",'영어 단어장'!B6)) | E6: =IF(OR(B6="",C6=""),"",IF(EXACT(LOWER(TRIM(C6)),LOWER(TRIM('영어 단어장'!B6))),"⭕","❌")) -> ⭕
A7: =ROW()-1 -> 6 | B7: =IF('영어 단어장'!C7="","",'영어 단어장'!C7) -> 변덕스러운 | D7: =IF(OR(C7="",'영어 단어장'!B7=""),"",IF(EXACT(LOWER(TRIM(C7)),LOWER(TRIM('영어 단어장'!B7))),"",'영어 단어장'!B7)) | E7: =IF(OR(B7="",C7=""),"",IF(EXACT(LOWER(TRIM(C7)),LOWER(TRIM('영어 단어장'!B7))),"⭕","❌"))
A8: =ROW()-1 -> 7 | B8: =IF('영어 단어장'!C8="","",'영어 단어장'!C8) -> 숙고하다 | D8: =IF(OR(C8="",'영어 단어장'!B8=""),"",IF(EXACT(LOWER(TRIM(C8)),LOWER(TRIM('영어 단어장'!B8))),"",'영어 단어장'!B8)) | E8: =IF(OR(B8="",C8=""),"",IF(EXACT(LOWER(TRIM(C8)),LOWER(TRIM('영어 단어장'!B8))),"⭕","❌"))
A9: =ROW()-1 -> 8 | B9: =IF('영어 단어장'!C9="","",'영어 단어장'!C9) -> 꼼꼼한, 세심한 | D9: =IF(OR(C9="",'영어 단어장'!B9=""),"",IF(EXACT(LOWER(TRIM(C9)),LOWER(TRIM('영어 단어장'!B9))),"",'영어 단어장'!B9)) | E9: =IF(OR(B9="",C9=""),"",IF(EXACT(LOWER(TRIM(C9)),LOWER(TRIM('영어 단어장'!B9))),"⭕","❌"))
A10: =ROW()-1 -> 9 | B10: =IF('영어 단어장'!C10="","",'영어 단어장'!C10) -> 영구적인 | D10: =IF(OR(C10="",'영어 단어장'!B10=""),"",IF(EXACT(LOWER(TRIM(C10)),LOWER(TRIM('영어 단어장'!B10))),"",'영어 단어장'!B10)) | E10: =IF(OR(B10="",C10=""),"",IF(EXACT(LOWER(TRIM(C10)),LOWER(TRIM('영어 단어장'!B10))),"⭕","❌"))
A11: =ROW()-1 -> 10 | B11: =IF('영어 단어장'!C11="","",'영어 단어장'!C11) -> 중복된, 불필요한 | D11: =IF(OR(C11="",'영어 단어장'!B11=""),"",IF(EXACT(LOWER(TRIM(C11)),LOWER(TRIM('영어 단어장'!B11))),"",'영어 단어장'!B11)) | E11: =IF(OR(B11="",C11=""),"",IF(EXACT(LOWER(TRIM(C11)),LOWER(TRIM('영어 단어장'!B11))),"⭕","❌"))
A12: =ROW()-1 -> 11 | B12: =IF('영어 단어장'!C12="","",'영어 단어장'!C12) -> 적절한, 충분한 | D12: =IF(OR(C12="",'영어 단어장'!B12=""),"",IF(EXACT(LOWER(TRIM(C12)),LOWER(TRIM('영어 단어장'!B12))),"",'영어 단어장'!B12)) | E12: =IF(OR(B12="",C12=""),"",IF(EXACT(LOWER(TRIM(C12)),LOWER(TRIM('영어 단어장'!B12))),"⭕","❌"))
A13: =ROW()-1 -> 12 | B13: =IF('영어 단어장'!C13="","",'영어 단어장'!C13) -> 꺼리는 | D13: =IF(OR(C13="",'영어 단어장'!B13=""),"",IF(EXACT(LOWER(TRIM(C13)),LOWER(TRIM('영어 단어장'!B13))),"",'영어 단어장'!B13)) | E13: =IF(OR(B13="",C13=""),"",IF(EXACT(LOWER(TRIM(C13)),LOWER(TRIM('영어 단어장'!B13))),"⭕","❌"))
A14: =ROW()-1 -> 13 | B14: =IF('영어 단어장'!C14="","",'영어 단어장'!C14) -> 진실한, 진짜의 | D14: =IF(OR(C14="",'영어 단어장'!B14=""),"",IF(EXACT(LOWER(TRIM(C14)),LOWER(TRIM('영어 단어장'!B14))),"",'영어 단어장'!B14)) | E14: =IF(OR(B14="",C14=""),"",IF(EXACT(LOWER(TRIM(C14)),LOWER(TRIM('영어 단어장'!B14))),"⭕","❌"))
A15: =ROW()-1 -> 14 | B15: =IF('영어 단어장'!C15="","",'영어 단어장'!C15) -> 일시적인 | D15: =IF(OR(C15="",'영어 단어장'!B15=""),"",IF(EXACT(LOWER(TRIM(C15)),LOWER(TRIM('영어 단어장'!B15))),"",'영어 단어장'!B15)) | E15: =IF(OR(B15="",C15=""),"",IF(EXACT(LOWER(TRIM(C15)),LOWER(TRIM('영어 단어장'!B15))),"⭕","❌"))
A16: =ROW()-1 -> 15 | B16: =IF('영어 단어장'!C16="","",'영어 단어장'!C16) -> 효율적인 | D16: =IF(OR(C16="",'영어 단어장'!B16=""),"",IF(EXACT(LOWER(TRIM(C16)),LOWER(TRIM('영어 단어장'!B16))),"",'영어 단어장'!B16)) | E16: =IF(OR(B16="",C16=""),"",IF(EXACT(LOWER(TRIM(C16)),LOWER(TRIM('영어 단어장'!B16))),"⭕","❌"))
A17: =ROW()-1 -> 16 | B17: =IF('영어 단어장'!C17="","",'영어 단어장'!C17) -> 유지하다 | D17: =IF(OR(C17="",'영어 단어장'!B17=""),"",IF(EXACT(LOWER(TRIM(C17)),LOWER(TRIM('영어 단어장'!B17))),"",'영어 단어장'!B17)) | E17: =IF(OR(B17="",C17=""),"",IF(EXACT(LOWER(TRIM(C17)),LOWER(TRIM('영어 단어장'!B17))),"⭕","❌"))
A18: =ROW()-1 -> 17 | B18: =IF('영어 단어장'!C18="","",'영어 단어장'!C18) -> 대략의, 근사치의 | D18: =IF(OR(C18="",'영어 단어장'!B18=""),"",IF(EXACT(LOWER(TRIM(C18)),LOWER(TRIM('영어 단어장'!B18))),"",'영어 단어장'!B18)) | E18: =IF(OR(B18="",C18=""),"",IF(EXACT(LOWER(TRIM(C18)),LOWER(TRIM('영어 단어장'!B18))),"⭕","❌"))
... A234: =ROW()-1 -> 233 | B234: =IF('영어 단어장'!C234="","",'영어 단어장'!C234) -> 안면의 | D234: =IF(OR(C234="",'영어 단어장'!B234=""),"",IF(EXACT(LOWER(TRIM(C234)),LOWER(TRIM('영어 단어장'!B234))),"",'영어 단어장'!B234)) | E234: =IF(OR(B234="",C234=""),"",IF(EXACT(LOWER(TRIM(C234)),LOWER(TRIM('영어 단어장'!B234))),"⭕","❌"))
A235: =ROW()-1 -> 234 | B235: =IF('영어 단어장'!C236="","",'영어 단어장'!C236) -> 인내, 참을성 | D235: =IF(OR(C235="",'영어 단어장'!B235=""),"",IF(EXACT(LOWER(TRIM(C235)),LOWER(TRIM('영어 단어장'!B235))),"",'영어 단어장'!B235)) | E235: =IF(OR(B235="",C235=""),"",IF(EXACT(LOWER(TRIM(C235)),LOWER(TRIM('영어 단어장'!B235))),"⭕","❌"))
A236: =ROW()-1 -> 235 | B236: =IF('영어 단어장'!C237="","",'영어 단어장'!C237) -> 잘못된 방향으로 이끌다 | D236: =IF(OR(C236="",'영어 단어장'!B236=""),"",IF(EXACT(LOWER(TRIM(C236)),LOWER(TRIM('영어 단어장'!B236))),"",'영어 단어장'!B236)) | E236: =IF(OR(B236="",C236=""),"",IF(EXACT(LOWER(TRIM(C236)),LOWER(TRIM('영어 단어장'!B236))),"⭕","❌"))
A237: =ROW()-1 -> 236 | B237: =IF('영어 단어장'!C238="","",'영어 단어장'!C238) -> 대출 | D237: =IF(OR(C237="",'영어 단어장'!B237=""),"",IF(EXACT(LOWER(TRIM(C237)),LOWER(TRIM('영어 단어장'!B237))),"",'영어 단어장'!B237)) | E237: =IF(OR(B237="",C237=""),"",IF(EXACT(LOWER(TRIM(C237)),LOWER(TRIM('영어 단어장'!B237))),"⭕","❌"))
A238: =ROW()-1 -> 237 | B238: =IF('영어 단어장'!C239="","",'영어 단어장'!C239) -> 논쟁, 토론 | D238: =IF(OR(C238="",'영어 단어장'!B238=""),"",IF(EXACT(LOWER(TRIM(C238)),LOWER(TRIM('영어 단어장'!B238))),"",'영어 단어장'!B238)) | E238: =IF(OR(B238="",C238=""),"",IF(EXACT(LOWER(TRIM(C238)),LOWER(TRIM('영어 단어장'!B238))),"⭕","❌"))
A239: =ROW()-1 -> 238 | B239: =IF('영어 단어장'!C239="","",'영어 단어장'!C239) -> 논쟁, 토론 | D239: =IF(OR(C239="",'영어 단어장'!B239=""),"",IF(EXACT(LOWER(TRIM(C239)),LOWER(TRIM('영어 단어장'!B239))),"",'영어 단어장'!B239)) | E239: =IF(OR(B239="",C239=""),"",IF(EXACT(LOWER(TRIM(C239)),LOWER(TRIM('영어 단어장'!B239))),"⭕","❌"))
A240: =ROW()-1 -> 239 | B240: =IF('영어 단어장'!C240="","",'영어 단어장'!C240) -> 수치, 인물, 생각하다 | D240: =IF(OR(C240="",'영어 단어장'!B240=""),"",IF(EXACT(LOWER(TRIM(C240)),LOWER(TRIM('영어 단어장'!B240))),"",'영어 단어장'!B240)) | E240: =IF(OR(B240="",C240=""),"",IF(EXACT(LOWER(TRIM(C240)),LOWER(TRIM('영어 단어장'!B240))),"⭕","❌"))
A241: =ROW()-1 -> 240 | B241: =IF('영어 단어장'!C241="","",'영어 단어장'!C241) -> 가치가 있는 | D241: =IF(OR(C241="",'영어 단어장'!B241=""),"",IF(EXACT(LOWER(TRIM(C241)),LOWER(TRIM('영어 단어장'!B241))),"",'영어 단어장'!B241)) | E241: =IF(OR(B241="",C241=""),"",IF(EXACT(LOWER(TRIM(C241)),LOWER(TRIM('영어 단어장'!B241))),"⭕","❌"))
A242: =ROW()-1 -> 241 | B242: =IF('영어 단어장'!C242="","",'영어 단어장'!C242) -> 지속적인 | D242: =IF(OR(C242="",'영어 단어장'!B242=""),"",IF(EXACT(LOWER(TRIM(C242)),LOWER(TRIM('영어 단어장'!B242))),"",'영어 단어장'!B242)) | E242: =IF(OR(B242="",C242=""),"",IF(EXACT(LOWER(TRIM(C242)),LOWER(TRIM('영어 단어장'!B242))),"⭕","❌"))
A243: =ROW()-1 -> 242 | B243: =IF('영어 단어장'!C243="","",'영어 단어장'!C243) -> 비판 | D243: =IF(OR(C243="",'영어 단어장'!B243=""),"",IF(EXACT(LOWER(TRIM(C243)),LOWER(TRIM('영어 단어장'!B243))),"",'영어 단어장'!B243)) | E243: =IF(OR(B243="",C243=""),"",IF(EXACT(LOWER(TRIM(C243)),LOWER(TRIM('영어 단어장'!B243))),"⭕","❌"))
A244: =ROW()-1 -> 243 | B244: =IF('영어 단어장'!C244="","",'영어 단어장'!C244) -> 짧은, 보고서, 개요 | D244: =IF(OR(C244="",'영어 단어장'!B244=""),"",IF(EXACT(LOWER(TRIM(C244)),LOWER(TRIM('영어 단어장'!B244))),"",'영어 단어장'!B244)) | E244: =IF(OR(B244="",C244=""),"",IF(EXACT(LOWER(TRIM(C244)),LOWER(TRIM('영어 단어장'!B244))),"⭕","❌"))
A245: =ROW()-1 -> 244 | B245: =IF('영어 단어장'!C245="","",'영어 단어장'!C245) -> 비난, 고소, 죄 | D245: =IF(OR(C245="",'영어 단어장'!B245=""),"",IF(EXACT(LOWER(TRIM(C245)),LOWER(TRIM('영어 단어장'!B245))),"",'영어 단어장'!B245)) | E245: =IF(OR(B245="",C245=""),"",IF(EXACT(LOWER(TRIM(C245)),LOWER(TRIM('영어 단어장'!B245))),"⭕","❌"))
A246: =ROW()-1 -> 245 | B246: =IF('영어 단어장'!C246="","",'영어 단어장'!C246) -> 기증자 | D246: =IF(OR(C246="",'영어 단어장'!B246=""),"",IF(EXACT(LOWER(TRIM(C246)),LOWER(TRIM('영어 단어장'!B246))),"",'영어 단어장'!B246)) | E246: =IF(OR(B246="",C246=""),"",IF(EXACT(LOWER(TRIM(C246)),LOWER(TRIM('영어 단어장'!B246))),"⭕","❌"))
A247: =ROW()-1 -> 246 | B247: =IF('영어 단어장'!C247="","",'영어 단어장'!C247) -> 자연, 본성, 성격 | D247: =IF(OR(C247="",'영어 단어장'!B247=""),"",IF(EXACT(LOWER(TRIM(C247)),LOWER(TRIM('영어 단어장'!B247))),"",'영어 단어장'!B247)) | E247: =IF(OR(B247="",C247=""),"",IF(EXACT(LOWER(TRIM(C247)),LOWER(TRIM('영어 단어장'!B247))),"⭕","❌"))
A248: =ROW()-1 -> 247 | B248: =IF('영어 단어장'!C248="","",'영어 단어장'!C248) -> ~중에 | D248: =IF(OR(C248="",'영어 단어장'!B248=""),"",IF(EXACT(LOWER(TRIM(C248)),LOWER(TRIM('영어 단어장'!B248))),"",'영어 단어장'!B248)) | E248: =IF(OR(B248="",C248=""),"",IF(EXACT(LOWER(TRIM(C248)),LOWER(TRIM('영어 단어장'!B248))),"⭕","❌"))
A249: =ROW()-1 -> 248 | B249: =IF('영어 단어장'!C249="","",'영어 단어장'!C249) -> 자산 | D249: =IF(OR(C249="",'영어 단어장'!B249=""),"",IF(EXACT(LOWER(TRIM(C249)),LOWER(TRIM('영어 단어장'!B249))),"",'영어 단어장'!B249)) | E249: =IF(OR(B249="",C249=""),"",IF(EXACT(LOWER(TRIM(C249)),LOWER(TRIM('영어 단어장'!B249))),"⭕","❌"))
A250: =ROW()-1 -> 249 | B250: =IF('영어 단어장'!C250="","",'영어 단어장'!C250) -> 굴욕, 창피를 주기 | D250: =IF(OR(C250="",'영어 단어장'!B250=""),"",IF(EXACT(LOWER(TRIM(C250)),LOWER(TRIM('영어 단어장'!B250))),"",'영어 단어장'!B250)) | E250: =IF(OR(B250="",C250=""),"",IF(EXACT(LOWER(TRIM(C250)),LOWER(TRIM('영어 단어장'!B250))),"⭕","❌"))
... A501: =ROW()-1 -> 500 | B501: =IF('영어 단어장'!C501="","",'영어 단어장'!C501) -> 아픈 | D501: =IF(OR(C501="",'영어 단어장'!B501=""),"",IF(EXACT(LOWER(TRIM(C501)),LOWER(TRIM('영어 단어장'!B501))),"",'영어 단어장'!B501)) | E501: =IF(OR(B501="",C501=""),"",IF(EXACT(LOWER(TRIM(C501)),LOWER(TRIM('영어 단어장'!B501))),"⭕","❌"))

Sheet 부사절 접속사 정리
A1: 부사절 접속사 / 전치사 / 접속부사 총정리
A2: ★ 접속사 + 주어+동사 (S+V) | 전치사 + 명사/동명사 | 접속부사 = 부사(문장 연결X, 앞에 ; 또는 . 필요)
A4: 의미 분류 | B4: 접속사 (+ S+V) | C4: 전치사 (+ 명사) | D4: 접속부사 (부사) | E4: 암기 TIP
A5: 시간 ~할 때, ~하는 동안 | B5: when (~ 할 때) while (~하는 동안) as (~할 때, ~하면서) before (~전에) after (~후에) until (~까지) once (~하자마자) as soon as (~하자마자) | C5: during (~동안) before (~전에) after (~후에) until (~까지) | D5: meanwhile (그 동안에) then (그때, 그 다음에) | E5: during + 명사 (기간) while + S+V → 가장 자주 출제!
A6: 원인·이유 ~때문에 | B6: because (~때문에) since (~이므로) now that (~이니까) as (~이므로) | C6: because of (~때문에) due to (~때문에) on account of (~때문에) | D6: therefore (그러므로) thus (따라서) hence (그래서) consequently (결과적으로) | E6: because + S+V because of + 명사 → 시험 단골!
A7: 양보 ~에도 불구하고 | B7: although (~에도 불구하고) though (~이지만) even though (~에도 불구하고) while (~인 반면에) whereas (~인 반면에) | C7: despite (~에도 불구하고) in spite of (~에도 불구하고) | D7: however (그러나) nevertheless (그럼에도) nonetheless (그럼에도) | E7: although + S+V despite + 명사 → 최빈출 유형!
A8: 조건 ~한다면 | B8: if (만약 ~라면) unless (~하지 않는 한) provided (that) (~라면) as long as (~하는 한) in case (~의 경우에) even if (설사 ~라도) only if (오직 ~할 때만) whether ~ or (~이든 아니든) | C8: in case of (~의 경우에) without (~없이) | D8: otherwise (그렇지 않으면) | E8: unless = if ~ not → 부정 중복 주의!
A9: 결과·목적 ~하기 위해 | B9: so that (~하기 위해) in order that (~하기 위해) so ~ that (너무~해서) | C9: for (~을 위해) in order to (~하기 위해) | D9: therefore (그러므로) as a result (결과적으로) consequently (결과적으로) accordingly (따라서) | E9: so that + S + can/will → 목적 표현!
A10: 대조·반면 ~인 반면 | B10: while (~인 반면) whereas (~인 반면) | D10: however (그러나) on the other hand (반면에) in contrast (대조적으로) conversely (반대로) instead (대신에) | E10: while/whereas + S+V → 대조 접속사!
A11: 부가·추가 게다가 | C11: in addition to (~에 더하여) apart from (~외에도) | D11: furthermore (게다가) moreover (더욱이) in addition (게다가) also (또한) besides (게다가) | E11: 접속부사만 있는 의미! → 빈칸 출제 多
A12: 기타 | B12: as if / as though (마치 ~인 것처럼) wherever (~하는 곳 어디든) | C12: according to (~에 따르면) regarding (~에 관하여) concerning (~에 관하여) | D12: alternatively (대안으로) in fact (사실) for example (예를 들어)
A14: 📌 핵심 구별법: 빈칸 뒤에 S+V → 접속사 | 빈칸 뒤에 명사/동명사 → 전치사 | 앞 문장 완결 + , → 접속부사
A15: 📌 접속부사는 접속사가 아님! → 두 절을 연결 못함. 반드시 세미콜론(;) 또는 마침표(.) 뒤에 사용

Sheet Sheet2
A1: No. | B1: 영어 단어 | C1: 뜻 | D1: 품사 | E1: 예문 | F1: 암기 체크 | G1: 입력 날짜 | H1: 구분
A2: 1 | B2: when | C2: ~할 때 | D2: 부사절 접속사 | E2: When I arrived at the station, the train had already left.
A3: 2 | B3: while | C3: ~하는 동안 | D3: 부사절 접속사 | E3: She listened to music while she was studying.
A4: 3 | B4: while | C4: ~인 반면에(대조) | D4: 부사절 접속사 | E4: While Tom is outgoing, his brother is very shy.
A5: 4 | B5: as | C5: ~할 때, ~하면서 | D5: 부사절 접속사 | E5: As I was walking home, I ran into an old friend.
A6: 5 | B6: as | C6: ~이므로(이유) | D6: 부사절 접속사 | E6: As it was raining heavily, we decided to stay indoors.
A7: 6 | B7: before | C7: ~하기 전에 | D7: 부사절 접속사 | E7: You should finish your homework before you go out.
A8: 7 | B8: after | C8: ~한 후에 | D8: 부사절 접속사 | E8: After she graduated from college, she moved to New York.
A9: 8 | B9: until | C9: ~할 때까지 | D9: 부사절 접속사 | E9: I will wait here until you come back.
A10: 9 | B10: once | C10: 일단 ~하면 | D10: 부사절 접속사 | E10: Once you understand the basics, everything becomes easier.
A11: 10 | B11: as soon as | C11: ~하자마자 | D11: 부사절 접속사 | E11: As soon as I heard the news, I called my parents.
A12: 11 | B12: because | C12: ~때문에 | D12: 부사절 접속사 | E12: He was late because he missed the bus.
A13: 12 | B13: since | C13: ~이므로(이유) | D13: 부사절 접속사 | E13: Since she had no experience, she struggled at first.
... A72: 71 | B72: for example | C72: 예를 들어 | D72: 접속부사 | E72: Many countries are multilingual; for example, Switzerland has four official languages.
